<?xml version="1.0" encoding="utf-8"?>
<robot xmlns:xacro="http://wiki.ros.org/xacro">

  <xacro:macro name="ur5_robot" params="parent *origin">

  <material name="grey">
    <color rgba="0.2 0.2 0.2 1.0"/>
  </material>

  <joint name="base_joint" type="fixed">
    <parent link="${parent}"/>
    <child link="base_link" />
    <xacro:insert_block name="origin" />
  </joint>

  <link name="base_link">
    <visual>
      <geometry>
        <mesh filename="package://ros2_descriptions/description/meshes/ur5/visual/base.dae"/>
      </geometry>
      <material name="grey"/>
    </visual>
    <collision>
      <geometry>
        <mesh filename="package://ros2_descriptions/description/meshes/ur5/collision/base.stl"/>
      </geometry>
    </collision>
    <inertial>
      <mass value="4.0000"/>
      <origin rpy="0 0 0" xyz="0.0 0.0 0.0"/>
      <inertia
        ixx="0.00443333156" ixy="0.0" ixz="0.0"
        iyy="0.00443333156" iyz="0.0"
        izz="0.0072"/>
    </inertial>
  </link>

  <joint name="shoulder_pan_joint" type="revolute">
    <parent link="base_link"/>
    <child link="shoulder_link"/>
    <origin rpy="0.0 0.0 0.0" xyz="0.0 0.0 0.089159"/>
    <axis xyz="0 0 1"/>
    <limit effort="150.0" lower="-6.28318530718" upper="6.28318530718" velocity="3.15"/>
    <dynamics damping="0.20" friction="0.0"/>
  </joint>

  <link name="shoulder_link">
    <visual>
      <geometry>
        <mesh filename="package://ros2_descriptions/description/meshes/ur5/visual/shoulder.dae"/>
      </geometry>
      <material name="grey"/>
    </visual>
    <collision>
      <geometry>
        <mesh filename="package://ros2_descriptions/description/meshes/ur5/collision/shoulder.stl"/>
      </geometry>
    </collision>
    <inertial>
      <mass value="3.7000"/>
      <origin rpy="0 0 0" xyz="0.0 0.0 0.0"/>
      <inertia
        ixx="0.014972358333333331" ixy="0.0" ixz="0.0"
        iyy="0.014972358333333331" iyz="0.0"
        izz="0.01040625"/>
    </inertial>
  </link>

  <joint name="shoulder_lift_joint" type="revolute">
    <parent link="shoulder_link"/>
    <child link="upper_arm_link"/>
    <origin rpy="0.0 1.57079632679 0.0" xyz="0.0 0.13585 0.0"/>
    <axis xyz="0 1 0"/>
    <limit effort="150.0" lower="-6.28318530718" upper="6.28318530718" velocity="3.15"/>
    <dynamics damping="0.10" friction="0.0"/>
  </joint>

  <link name="upper_arm_link">
    <visual>
      <geometry>
        <mesh filename="package://ros2_descriptions/description/meshes/ur5/visual/upperarm.dae"/>
      </geometry>
      <material name="grey"/>
    </visual>
    <collision>
      <geometry>
        <mesh filename="package://ros2_descriptions/description/meshes/ur5/collision/upperarm.stl"/>
      </geometry>
    </collision>
    <inertial>
      <mass value="8.3930"/>
      <origin rpy="0 0 0" xyz="0.0 0.0 0.28"/>
      <inertia
        ixx="0.13388583541666665" ixy="0.0" ixz="0.0"
        iyy="0.13388583541666665" iyz="0.0"
        izz="0.0151074"/>
    </inertial>
  </link>

  <joint name="elbow_joint" type="revolute">
    <parent link="upper_arm_link"/>
    <child link="forearm_link"/>
    <origin rpy="0.0 0.0 0.0" xyz="0.0 -0.1197 0.425"/>
    <axis xyz="0 1 0"/>
    <limit effort="150.0" lower="-3.14159265359" upper="3.14159265359" velocity="3.15"/>
    <dynamics damping="0.10" friction="0.0"/>
  </joint>

  <link name="forearm_link">
    <visual>
      <geometry>
        <mesh filename="package://ros2_descriptions/description/meshes/ur5/visual/forearm.dae"/>
      </geometry>
      <material name="grey"/>
    </visual>
    <collision>
      <geometry>
        <mesh filename="package://ros2_descriptions/description/meshes/ur5/collision/forearm.stl"/>
      </geometry>
    </collision>
    <inertial>
      <mass value="2.3300"/>
      <origin rpy="0 0 0" xyz="0.0 0.0 0.25"/>
      <inertia
        ixx="0.031216803515624995" ixy="0.0" ixz="0.0"
        iyy="0.031216803515624995" iyz="0.0"
        izz="0.004095"/>
    </inertial>
  </link>

  <joint name="wrist_1_joint" type="revolute">
    <parent link="forearm_link"/>
    <child link="wrist_1_link"/>
    <origin rpy="0.0 1.57079632679 0.0" xyz="0.0 0.0 0.39225"/>
    <axis xyz="0 1 0"/>
    <limit effort="28.0" lower="-6.28318530718" upper="6.28318530718" velocity="3.2"/>
    <dynamics damping="0.20" friction="0.0"/>
  </joint>

  <link name="wrist_1_link">
    <visual>
      <geometry>
        <mesh filename="package://ros2_descriptions/description/meshes/ur5/visual/wrist1.dae"/>
      </geometry>
      <material name="grey"/>
    </visual>
    <collision>
      <geometry>
        <mesh filename="package://ros2_descriptions/description/meshes/ur5/collision/wrist1.stl"/>
      </geometry>
    </collision>
    <inertial>
      <mass value="1.2190"/>
      <origin rpy="0 0 0" xyz="0.0 0.0 0.0"/>
      <inertia
        ixx="0.002013889583333333" ixy="0.0" ixz="0.0"
        iyy="0.002013889583333333" iyz="0.0"
        izz="0.0021942"/>
    </inertial>
  </link>

  <joint name="wrist_2_joint" type="revolute">
    <parent link="wrist_1_link"/>
    <child link="wrist_2_link"/>
    <origin rpy="0.0 0.0 0.0" xyz="0.0 0.093 0.0"/>
    <axis xyz="0 0 1"/>
    <limit effort="28.0" lower="-6.28318530718" upper="6.28318530718" velocity="3.2"/>
    <dynamics damping="0.20" friction="0.0"/>
  </joint>

  <link name="wrist_2_link">
    <visual>
      <geometry>
        <mesh filename="package://ros2_descriptions/description/meshes/ur5/visual/wrist2.dae"/>
      </geometry>
      <material name="grey"/>
    </visual>
    <collision>
      <geometry>
        <mesh filename="package://ros2_descriptions/description/meshes/ur5/collision/wrist2.stl"/>
      </geometry>
    </collision>
    <inertial>
      <mass value="1.2190"/>
      <origin rpy="0 0 0" xyz="0.0 0.0 0.0"/>
      <inertia
        ixx="0.0018310395833333333" ixy="0.0" ixz="0.0"
        iyy="0.0018310395833333333" iyz="0.0"
        izz="0.0021942"/>
    </inertial>
  </link>

  <joint name="wrist_3_joint" type="revolute">
    <parent link="wrist_2_link"/>
    <child link="wrist_3_link"/>
    <origin rpy="0.0 0.0 0.0" xyz="0.0 0.0 0.09465"/>
    <axis xyz="0 1 0"/>
    <limit effort="28.0" lower="-6.28318530718" upper="6.28318530718" velocity="3.2"/>
    <dynamics damping="0.20" friction="0.0"/>
  </joint>

  <link name="wrist_3_link">
    <visual>
      <geometry>
        <mesh filename="package://ros2_descriptions/description/meshes/ur5/visual/wrist3.dae"/>
      </geometry>
      <material name="grey"/>
    </visual>
    <collision>
      <geometry>
        <cylinder radius="0.037" length="0.035" />
      </geometry>
      <origin rpy="1.57079632679 0 0" xyz="0.0 0.065 0.0"/>
    </collision>
    <inertial>
      <mass value="0.18790"/>
      <origin rpy="0 0 0" xyz="0.0 0.0 0.0"/>
      <inertia
        ixx="8.062475833333332e-05" ixy="0.0" ixz="0.0"
        iyy="8.062475833333332e-05" iyz="0.0"
        izz="0.0001321171875"/>
    </inertial>
  </link>

  <joint name="ee_fixed_joint" type="fixed">
    <parent link="wrist_3_link"/>
    <child link="ee_link"/>
    <origin rpy="0.0 0.0 1.57079632679" xyz="0.0 0.0823 0.0"/>
  </joint>

  <link name="ee_link">
  <!-- Bota Systems AG Rokubi FT sensor -->
    <visual>
      <geometry>
        <cylinder radius="0.024" length="0.030" />
      </geometry>
      <origin rpy="0 1.57079632679 0" xyz="0.016 0.0 0.0"/>
      <material name="Orange">
        <color rgba="0.8 0.4 0.0 1.0"/>
      </material>
    </visual>
    <collision name="sensor_body">
      <geometry>
        <cylinder radius="0.024" length="0.030" />
      </geometry>
      <origin rpy="0 1.57079632679 0" xyz="0.016 0.0 0.0"/>
      <max_contacts>6</max_contacts>
    </collision>
    <inertial>
      <!-- mass value="0.118"/ -->
      <mass value="0.018"/>
      <origin rpy="0 1.57079632679 0" xyz="0.016 0.0 0.0"/>
      <inertia
        ixx="8.00e-05" ixy="0.0" ixz="0.0"
        iyy="8.00e-05" iyz="0.0"
        izz="1.40e-04"/>
    </inertial>
  </link>

  </xacro:macro>

</robot>
